Workbook

Sheet Read me
A1: Restaurant OS - pages, features and who has access
A3: Built on 2026-09-28 from the repository at C:\dev\restaurant-os, branch feat/m11-communication.
A4: Nothing here is estimated. Pages come from frontend/src/staff/App.tsx and frontend/src/guest/App.tsx.
A5: Roles and permissions come from backend/app/core/permissions.json, which is the single source of truth
A6: the API enforces on every request.
A8: Sheets
A9: Pages - every screen in the product, grouped by area, with the permission its route demands and a Yes/- per role.
A10: Features & actions - all 55 permissions, which is the honest feature list, since a permission is one thing a person may do.
A11: Roles - the nine role templates, their seniority rank and their totals.
A12: Permission matrix - the raw grid the other sheets compute from. This is the only sheet holding typed data.
A14: How to read the access columns
A15: Yes the role template grants the permission that route or action requires.
... A34: This was not fixed, because the request was for an inventory.

Sheet Pages
A1: Area | B1: Page / screen | C1: Route | D1: Surface | E1: What it does | F1: Permission required | G1: Owner | H1: Administrator | I1: Manager | J1: Chef | K1: Store Manager | L1: Accountant | M1: Kitchen Staff | N1: Waiter | O1: Cleaner
A2: Access & account | B2: Sign in | C2: /login | D2: Staff (web/PWA) | E2: Email or phone plus password; issues the session every other screen needs. | F2: (none - every role) | G2: =IF($F2="(none - every role)","All",IF($F2="DEV","Dev build",IF($F2="GUEST","n/a - guest",IFERROR(IF(INDEX('Permission matrix'!$B$2:$J$56,MATCH($F2,'Permission matrix'!$A$2:$A$56,0),MATCH(G$1,'Permission matrix'!$B$1:$J$1,0))=1,"Yes","-"),"?")))) | H2: =IF($F2="(none - every role)","All",IF($F2="DEV","Dev build",IF($F2="GUEST","n/a - guest",IFERROR(IF(INDEX('Permission matrix'!$B$2:$J$56,MATCH($F2,'Permission matrix'!$A$2:$A$56,0),MATCH(H$1,'Permission matrix'!$B$1:$J$1,0))=1,"Yes","-"),"?")))) | I2: =IF($F2="(none - every role)","All",IF($F2="DEV","Dev build",IF($F2="GUEST","n/a - guest",IFERROR(IF(INDEX('Permission matrix'!$B$2:$J$56,MATCH($F2,'Permission matrix'!$A$2:$A$56,0),MATCH(I$1,'Permission matrix'!$B$1:$J$1,0))=1,"Yes","-"),"?")))) | J2: =IF($F2="(none - every role)","All",IF($F2="DEV","Dev build",IF($F2="GUEST","n/a - guest",IFERROR(IF(INDEX('Permission matrix'!$B$2:$J$56,MATCH($F2,'Permission matrix'!$A$2:$A$56,0),MATCH(J$1,'Permission matrix'!$B$1:$J$1,0))=1,"Yes","-"),"?")))) | K2: =IF($F2="(none - every role)","All",IF($F2="DEV","Dev build",IF($F2="GUEST","n/a - guest",IFERROR(IF(INDEX('Permission matrix'!$B$2:$J$56,MATCH($F2,'Permission matrix'!$A$2:$A$56,0),MATCH(K$1,'Permission matrix'!$B$1:$J$1,0))=1,"Yes","-"),"?")))) | L2: =IF($F2="(none - every role)","All",IF($F2="DEV","Dev build",IF($F2="GUEST","n/a - guest",IFERROR(IF(INDEX('Permission matrix'!$B$2:$J$56,MATCH($F2,'Permission matrix'!$A$2:$A$56,0),MATCH(L$1,'Permission matrix'!$B$1:$J$1,0))=1,"Yes","-"),"?")))) | M2: =IF($F2="(none - every role)","All",IF($F2="DEV","Dev build",IF($F2="GUEST","n/a - guest",IFERROR(IF(INDEX('Permission matrix'!$B$2:$J$56,MATCH($F2,'Permission matrix'!$A$2:$A$56,0),MATCH(M$1,'Permission matrix'!$B$1:$J$1,0))=1,"Yes","-"),"?")))) | N2: =IF($F2="(none - every role)","All",IF($F2="DEV","Dev build",IF($F2="GUEST","n/a - guest",IFERROR(IF(INDEX('Permission matrix'!$B$2:$J$56,MATCH($F2,'Permission matrix'!$A$2:$A$56,0),MATCH(N$1,'Permission matrix'!$B$1:$J$1,0))=1,"Yes","-"),"?")))) | O2: =IF($F2="(none - every role)","All",IF($F2="DEV","Dev build",IF($F2="GUEST","n/a - guest",IFERROR(IF(INDEX('Permission matrix'!$B$2:$J$56,MATCH($F2,'Permission matrix'!$A$2:$A$56,0),MATCH(O$1,'Permission matrix'!$B$1:$J$1,0))=1,"Yes","-"),"?"))))
A3: Access & account | B3: Home | C3: / | D3: Staff (web/PWA) | E3: Landing page. Lists the kitchen, store and diner screens the header does not carry. | F3: (none - every role) | G3: =IF($F3="(none - every role)","All",IF($F3="DEV","Dev build",IF($F3="GUEST","n/a - guest",IFERROR(IF(INDEX('Permission matrix'!$B$2:$J$56,MATCH($F3,'Permission matrix'!$A$2:$A$56,0),MATCH(G$1,'Permission matrix'!$B$1:$J$1,0))=1,"Yes","-"),"?")))) | H3: =IF($F3="(none - every role)","All",IF($F3="DEV","Dev build",IF($F3="GUEST","n/a - guest",IFERROR(IF(INDEX('Permission matrix'!$B$2:$J$56,MATCH($F3,'Permission matrix'!$A$2:$A$56,0),MATCH(H$1,'Permission matrix'!$B$1:$J$1,0))=1,"Yes","-"),"?")))) | I3: =IF($F3="(none - every role)","All",IF($F3="DEV","Dev build",IF($F3="GUEST","n/a - guest",IFERROR(IF(INDEX('Permission matrix'!$B$2:$J$56,MATCH($F3,'Permission matrix'!$A$2:$A$56,0),MATCH(I$1,'Permission matrix'!$B$1:$J$1,0))=1,"Yes","-"),"?")))) | J3: =IF($F3="(none - every role)","All",IF($F3="DEV","Dev build",IF($F3="GUEST","n/a - guest",IFERROR(IF(INDEX('Permission matrix'!$B$2:$J$56,MATCH($F3,'Permission matrix'!$A$2:$A$56,0),MATCH(J$1,'Permission matrix'!$B$1:$J$1,0))=1,"Yes","-"),"?")))) | K3: =IF($F3="(none - every role)","All",IF($F3="DEV","Dev build",IF($F3="GUEST","n/a - guest",IFERROR(IF(INDEX('Permission matrix'!$B$2:$J$56,MATCH($F3,'Permission matrix'!$A$2:$A$56,0),MATCH(K$1,'Permission matrix'!$B$1:$J$1,0))=1,"Yes","-"),"?")))) | L3: =IF($F3="(none - every role)","All",IF($F3="DEV","Dev build",IF($F3="GUEST","n/a - guest",IFERROR(IF(INDEX('Permission matrix'!$B$2:$J$56,MATCH($F3,'Permission matrix'!$A$2:$A$56,0),MATCH(L$1,'Permission matrix'!$B$1:$J$1,0))=1,"Yes","-"),"?")))) | M3: =IF($F3="(none - every role)","All",IF($F3="DEV","Dev build",IF($F3="GUEST","n/a - guest",IFERROR(IF(INDEX('Permission matrix'!$B$2:$J$56,MATCH($F3,'Permission matrix'!$A$2:$A$56,0),MATCH(M$1,'Permission matrix'!$B$1:$J$1,0))=1,"Yes","-"),"?")))) | N3: =IF($F3="(none - every role)","All",IF($F3="DEV","Dev build",IF($F3="GUEST","n/a - guest",IFERROR(IF(INDEX('Permission matrix'!$B$2:$J$56,MATCH($F3,'Permission matrix'!$A$2:$A$56,0),MATCH(N$1,'Permission matrix'!$B$1:$J$1,0))=1,"Yes","-"),"?")))) | O3: =IF($F3="(none - every role)","All",IF($F3="DEV","Dev build",IF($F3="GUEST","n/a - guest",IFERROR(IF(INDEX('Permission matrix'!$B$2:$J$56,MATCH($F3,'Permission matrix'!$A$2:$A$56,0),MATCH(O$1,'Permission matrix'!$B$1:$J$1,0))=1,"Yes","-"),"?"))))
A4: Access & account | B4: My profile | C4: /profile | D4: Staff (web/PWA) | E4: Own name, contact details and password change. | F4: (none - every role) | G4: =IF($F4="(none - every role)","All",IF($F4="DEV","Dev build",IF($F4="GUEST","n/a - guest",IFERROR(IF(INDEX('Permission matrix'!$B$2:$J$56,MATCH($F4,'Permission matrix'!$A$2:$A$56,0),MATCH(G$1,'Permission matrix'!$B$1:$J$1,0))=1,"Yes","-"),"?")))) | H4: =IF($F4="(none - every role)","All",IF($F4="DEV","Dev build",IF($F4="GUEST","n/a - guest",IFERROR(IF(INDEX('Permission matrix'!$B$2:$J$56,MATCH($F4,'Permission matrix'!$A$2:$A$56,0),MATCH(H$1,'Permission matrix'!$B$1:$J$1,0))=1,"Yes","-"),"?")))) | I4: =IF($F4="(none - every role)","All",IF($F4="DEV","Dev build",IF($F4="GUEST","n/a - guest",IFERROR(IF(INDEX('Permission matrix'!$B$2:$J$56,MATCH($F4,'Permission matrix'!$A$2:$A$56,0),MATCH(I$1,'Permission matrix'!$B$1:$J$1,0))=1,"Yes","-"),"?")))) | J4: =IF($F4="(none - every role)","All",IF($F4="DEV","Dev build",IF($F4="GUEST","n/a - guest",IFERROR(IF(INDEX('Permission matrix'!$B$2:$J$56,MATCH($F4,'Permission matrix'!$A$2:$A$56,0),MATCH(J$1,'Permission matrix'!$B$1:$J$1,0))=1,"Yes","-"),"?")))) | K4: =IF($F4="(none - every role)","All",IF($F4="DEV","Dev build",IF($F4="GUEST","n/a - guest",IFERROR(IF(INDEX('Permission matrix'!$B$2:$J$56,MATCH($F4,'Permission matrix'!$A$2:$A$56,0),MATCH(K$1,'Permission matrix'!$B$1:$J$1,0))=1,"Yes","-"),"?")))) | L4: =IF($F4="(none - every role)","All",IF($F4="DEV","Dev build",IF($F4="GUEST","n/a - guest",IFERROR(IF(INDEX('Permission matrix'!$B$2:$J$56,MATCH($F4,'Permission matrix'!$A$2:$A$56,0),MATCH(L$1,'Permission matrix'!$B$1:$J$1,0))=1,"Yes","-"),"?")))) | M4: =IF($F4="(none - every role)","All",IF($F4="DEV","Dev build",IF($F4="GUEST","n/a - guest",IFERROR(IF(INDEX('Permission matrix'!$B$2:$J$56,MATCH($F4,'Permission matrix'!$A$2:$A$56,0),MATCH(M$1,'Permission matrix'!$B$1:$J$1,0))=1,"Yes","-"),"?")))) | N4: =IF($F4="(none - every role)","All",IF($F4="DEV","Dev build",IF($F4="GUEST","n/a - guest",IFERROR(IF(INDEX('Permission matrix'!$B$2:$J$56,MATCH($F4,'Permission matrix'!$A$2:$A$56,0),MATCH(N$1,'Permission matrix'!$B$1:$J$1,0))=1,"Yes","-"),"?")))) | O4: =IF($F4="(none - every role)","All",IF($F4="DEV","Dev build",IF($F4="GUEST","n/a - guest",IFERROR(IF(INDEX('Permission matrix'!$B$2:$J$56,MATCH($F4,'Permission matrix'!$A$2:$A$56,0),MATCH(O$1,'Permission matrix'!$B$1:$J$1,0))=1,"Yes","-"),"?"))))
A5: Access & account | B5: Alerts | C5: /alerts | D5: Staff (web/PWA) | E5: Notification centre. Contents decided per condition by what the person can act on. | F5: (none - every role) | G5: =IF($F5="(none - every role)","All",IF($F5="DEV","Dev build",IF($F5="GUEST","n/a - guest",IFERROR(IF(INDEX('Permission matrix'!$B$2:$J$56,MATCH($F5,'Permission matrix'!$A$2:$A$56,0),MATCH(G$1,'Permission matrix'!$B$1:$J$1,0))=1,"Yes","-"),"?")))) | H5: =IF($F5="(none - every role)","All",IF($F5="DEV","Dev build",IF($F5="GUEST","n/a - guest",IFERROR(IF(INDEX('Permission matrix'!$B$2:$J$56,MATCH($F5,'Permission matrix'!$A$2:$A$56,0),MATCH(H$1,'Permission matrix'!$B$1:$J$1,0))=1,"Yes","-"),"?")))) | I5: =IF($F5="(none - every role)","All",IF($F5="DEV","Dev build",IF($F5="GUEST","n/a - guest",IFERROR(IF(INDEX('Permission matrix'!$B$2:$J$56,MATCH($F5,'Permission matrix'!$A$2:$A$56,0),MATCH(I$1,'Permission matrix'!$B$1:$J$1,0))=1,"Yes","-"),"?")))) | J5: =IF($F5="(none - every role)","All",IF($F5="DEV","Dev build",IF($F5="GUEST","n/a - guest",IFERROR(IF(INDEX('Permission matrix'!$B$2:$J$56,MATCH($F5,'Permission matrix'!$A$2:$A$56,0),MATCH(J$1,'Permission matrix'!$B$1:$J$1,0))=1,"Yes","-"),"?")))) | K5: =IF($F5="(none - every role)","All",IF($F5="DEV","Dev build",IF($F5="GUEST","n/a - guest",IFERROR(IF(INDEX('Permission matrix'!$B$2:$J$56,MATCH($F5,'Permission matrix'!$A$2:$A$56,0),MATCH(K$1,'Permission matrix'!$B$1:$J$1,0))=1,"Yes","-"),"?")))) | L5: =IF($F5="(none - every role)","All",IF($F5="DEV","Dev build",IF($F5="GUEST","n/a - guest",IFERROR(IF(INDEX('Permission matrix'!$B$2:$J$56,MATCH($F5,'Permission matrix'!$A$2:$A$56,0),MATCH(L$1,'Permission matrix'!$B$1:$J$1,0))=1,"Yes","-"),"?")))) | M5: =IF($F5="(none - every role)","All",IF($F5="DEV","Dev build",IF($F5="GUEST","n/a - guest",IFERROR(IF(INDEX('Permission matrix'!$B$2:$J$56,MATCH($F5,'Permission matrix'!$A$2:$A$56,0),MATCH(M$1,'Permission matrix'!$B$1:$J$1,0))=1,"Yes","-"),"?")))) | N5: =IF($F5="(none - every role)","All",IF($F5="DEV","Dev build",IF($F5="GUEST","n/a - guest",IFERROR(IF(INDEX('Permission matrix'!$B$2:$J$56,MATCH($F5,'Permission matrix'!$A$2:$A$56,0),MATCH(N$1,'Permission matrix'!$B$1:$J$1,0))=1,"Yes","-"),"?")))) | O5: =IF($F5="(none - every role)","All",IF($F5="DEV","Dev build",IF($F5="GUEST","n/a - guest",IFERROR(IF(INDEX('Permission matrix'!$B$2:$J$56,MATCH($F5,'Permission matrix'!$A$2:$A$56,0),MATCH(O$1,'Permission matrix'!$B$1:$J$1,0))=1,"Yes","-"),"?"))))
A6: Menu setting | B6: Menu | C6: /menu | D6: Staff (web/PWA) | E6: Categories, dishes and variants. Price control renders only for menu.price holders. | F6: menu.view | G6: =IF($F6="(none - every role)","All",IF($F6="DEV","Dev build",IF($F6="GUEST","n/a - guest",IFERROR(IF(INDEX('Permission matrix'!$B$2:$J$56,MATCH($F6,'Permission matrix'!$A$2:$A$56,0),MATCH(G$1,'Permission matrix'!$B$1:$J$1,0))=1,"Yes","-"),"?")))) | H6: =IF($F6="(none - every role)","All",IF($F6="DEV","Dev build",IF($F6="GUEST","n/a - guest",IFERROR(IF(INDEX('Permission matrix'!$B$2:$J$56,MATCH($F6,'Permission matrix'!$A$2:$A$56,0),MATCH(H$1,'Permission matrix'!$B$1:$J$1,0))=1,"Yes","-"),"?")))) | I6: =IF($F6="(none - every role)","All",IF($F6="DEV","Dev build",IF($F6="GUEST","n/a - guest",IFERROR(IF(INDEX('Permission matrix'!$B$2:$J$56,MATCH($F6,'Permission matrix'!$A$2:$A$56,0),MATCH(I$1,'Permission matrix'!$B$1:$J$1,0))=1,"Yes","-"),"?")))) | J6: =IF($F6="(none - every role)","All",IF($F6="DEV","Dev build",IF($F6="GUEST","n/a - guest",IFERROR(IF(INDEX('Permission matrix'!$B$2:$J$56,MATCH($F6,'Permission matrix'!$A$2:$A$56,0),MATCH(J$1,'Permission matrix'!$B$1:$J$1,0))=1,"Yes","-"),"?")))) | K6: =IF($F6="(none - every role)","All",IF($F6="DEV","Dev build",IF($F6="GUEST","n/a - guest",IFERROR(IF(INDEX('Permission matrix'!$B$2:$J$56,MATCH($F6,'Permission matrix'!$A$2:$A$56,0),MATCH(K$1,'Permission matrix'!$B$1:$J$1,0))=1,"Yes","-"),"?")))) | L6: =IF($F6="(none - every role)","All",IF($F6="DEV","Dev build",IF($F6="GUEST","n/a - guest",IFERROR(IF(INDEX('Permission matrix'!$B$2:$J$56,MATCH($F6,'Permission matrix'!$A$2:$A$56,0),MATCH(L$1,'Permission matrix'!$B$1:$J$1,0))=1,"Yes","-"),"?")))) | M6: =IF($F6="(none - every role)","All",IF($F6="DEV","Dev build",IF($F6="GUEST","n/a - guest",IFERROR(IF(INDEX('Permission matrix'!$B$2:$J$56,MATCH($F6,'Permission matrix'!$A$2:$A$56,0),MATCH(M$1,'Permission matrix'!$B$1:$J$1,0))=1,"Yes","-"),"?")))) | N6: =IF($F6="(none - every role)","All",IF($F6="DEV","Dev build",IF($F6="GUEST","n/a - guest",IFERROR(IF(INDEX('Permission matrix'!$B$2:$J$56,MATCH($F6,'Permission matrix'!$A$2:$A$56,0),MATCH(N$1,'Permission matrix'!$B$1:$J$1,0))=1,"Yes","-"),"?")))) | O6: =IF($F6="(none - every role)","All",IF($F6="DEV","Dev build",IF($F6="GUEST","n/a - guest",IFERROR(IF(INDEX('Permission matrix'!$B$2:$J$56,MATCH($F6,'Permission matrix'!$A$2:$A$56,0),MATCH(O$1,'Permission matrix'!$B$1:$J$1,0))=1,"Yes","-"),"?"))))
A7: Menu setting | B7: Dish detail | C7: /menu/:itemId | D7: Staff (web/PWA) | E7: One dish: variants, modifiers, allergens, availability, price and tax group. | F7: menu.view | G7: =IF($F7="(none - every role)","All",IF($F7="DEV","Dev build",IF($F7="GUEST","n/a - guest",IFERROR(IF(INDEX('Permission matrix'!$B$2:$J$56,MATCH($F7,'Permission matrix'!$A$2:$A$56,0),MATCH(G$1,'Permission matrix'!$B$1:$J$1,0))=1,"Yes","-"),"?")))) | H7: =IF($F7="(none - every role)","All",IF($F7="DEV","Dev build",IF($F7="GUEST","n/a - guest",IFERROR(IF(INDEX('Permission matrix'!$B$2:$J$56,MATCH($F7,'Permission matrix'!$A$2:$A$56,0),MATCH(H$1,'Permission matrix'!$B$1:$J$1,0))=1,"Yes","-"),"?")))) | I7: =IF($F7="(none - every role)","All",IF($F7="DEV","Dev build",IF($F7="GUEST","n/a - guest",IFERROR(IF(INDEX('Permission matrix'!$B$2:$J$56,MATCH($F7,'Permission matrix'!$A$2:$A$56,0),MATCH(I$1,'Permission matrix'!$B$1:$J$1,0))=1,"Yes","-"),"?")))) | J7: =IF($F7="(none - every role)","All",IF($F7="DEV","Dev build",IF($F7="GUEST","n/a - guest",IFERROR(IF(INDEX('Permission matrix'!$B$2:$J$56,MATCH($F7,'Permission matrix'!$A$2:$A$56,0),MATCH(J$1,'Permission matrix'!$B$1:$J$1,0))=1,"Yes","-"),"?")))) | K7: =IF($F7="(none - every role)","All",IF($F7="DEV","Dev build",IF($F7="GUEST","n/a - guest",IFERROR(IF(INDEX('Permission matrix'!$B$2:$J$56,MATCH($F7,'Permission matrix'!$A$2:$A$56,0),MATCH(K$1,'Permission matrix'!$B$1:$J$1,0))=1,"Yes","-"),"?")))) | L7: =IF($F7="(none - every role)","All",IF($F7="DEV","Dev build",IF($F7="GUEST","n/a - guest",IFERROR(IF(INDEX('Permission matrix'!$B$2:$J$56,MATCH($F7,'Permission matrix'!$A$2:$A$56,0),MATCH(L$1,'Permission matrix'!$B$1:$J$1,0))=1,"Yes","-"),"?")))) | M7: =IF($F7="(none - every role)","All",IF($F7="DEV","Dev build",IF($F7="GUEST","n/a - guest",IFERROR(IF(INDEX('Permission matrix'!$B$2:$J$56,MATCH($F7,'Permission matrix'!$A$2:$A$56,0),MATCH(M$1,'Permission matrix'!$B$1:$J$1,0))=1,"Yes","-"),"?")))) | N7: =IF($F7="(none - every role)","All",IF($F7="DEV","Dev build",IF($F7="GUEST","n/a - guest",IFERROR(IF(INDEX('Permission matrix'!$B$2:$J$56,MATCH($F7,'Permission matrix'!$A$2:$A$56,0),MATCH(N$1,'Permission matrix'!$B$1:$J$1,0))=1,"Yes","-"),"?")))) | O7: =IF($F7="(none - every role)","All",IF($F7="DEV","Dev build",IF($F7="GUEST","n/a - guest",IFERROR(IF(INDEX('Permission matrix'!$B$2:$J$56,MATCH($F7,'Permission matrix'!$A$2:$A$56,0),MATCH(O$1,'Permission matrix'!$B$1:$J$1,0))=1,"Yes","-"),"?"))))
A8: Menu setting | B8: Modifier groups | C8: /menu/options | D8: Staff (web/PWA) | E8: Option sets attached to dishes (spice level, add-ons, portion). | F8: menu.view | G8: =IF($F8="(none - every role)","All",IF($F8="DEV","Dev build",IF($F8="GUEST","n/a - guest",IFERROR(IF(INDEX('Permission matrix'!$B$2:$J$56,MATCH($F8,'Permission matrix'!$A$2:$A$56,0),MATCH(G$1,'Permission matrix'!$B$1:$J$1,0))=1,"Yes","-"),"?")))) | H8: =IF($F8="(none - every role)","All",IF($F8="DEV","Dev build",IF($F8="GUEST","n/a - guest",IFERROR(IF(INDEX('Permission matrix'!$B$2:$J$56,MATCH($F8,'Permission matrix'!$A$2:$A$56,0),MATCH(H$1,'Permission matrix'!$B$1:$J$1,0))=1,"Yes","-"),"?")))) | I8: =IF($F8="(none - every role)","All",IF($F8="DEV","Dev build",IF($F8="GUEST","n/a - guest",IFERROR(IF(INDEX('Permission matrix'!$B$2:$J$56,MATCH($F8,'Permission matrix'!$A$2:$A$56,0),MATCH(I$1,'Permission matrix'!$B$1:$J$1,0))=1,"Yes","-"),"?")))) | J8: =IF($F8="(none - every role)","All",IF($F8="DEV","Dev build",IF($F8="GUEST","n/a - guest",IFERROR(IF(INDEX('Permission matrix'!$B$2:$J$56,MATCH($F8,'Permission matrix'!$A$2:$A$56,0),MATCH(J$1,'Permission matrix'!$B$1:$J$1,0))=1,"Yes","-"),"?")))) | K8: =IF($F8="(none - every role)","All",IF($F8="DEV","Dev build",IF($F8="GUEST","n/a - guest",IFERROR(IF(INDEX('Permission matrix'!$B$2:$J$56,MATCH($F8,'Permission matrix'!$A$2:$A$56,0),MATCH(K$1,'Permission matrix'!$B$1:$J$1,0))=1,"Yes","-"),"?")))) | L8: =IF($F8="(none - every role)","All",IF($F8="DEV","Dev build",IF($F8="GUEST","n/a - guest",IFERROR(IF(INDEX('Permission matrix'!$B$2:$J$56,MATCH($F8,'Permission matrix'!$A$2:$A$56,0),MATCH(L$1,'Permission matrix'!$B$1:$J$1,0))=1,"Yes","-"),"?")))) | M8: =IF($F8="(none - every role)","All",IF($F8="DEV","Dev build",IF($F8="GUEST","n/a - guest",IFERROR(IF(INDEX('Permission matrix'!$B$2:$J$56,MATCH($F8,'Permission matrix'!$A$2:$A$56,0),MATCH(M$1,'Permission matrix'!$B$1:$J$1,0))=1,"Yes","-"),"?")))) | N8: =IF($F8="(none - every role)","All",IF($F8="DEV","Dev build",IF($F8="GUEST","n/a - guest",IFERROR(IF(INDEX('Permission matrix'!$B$2:$J$56,MATCH($F8,'Permission matrix'!$A$2:$A$56,0),MATCH(N$1,'Permission matrix'!$B$1:$J$1,0))=1,"Yes","-"),"?")))) | O8: =IF($F8="(none - every role)","All",IF($F8="DEV","Dev build",IF($F8="GUEST","n/a - guest",IFERROR(IF(INDEX('Permission matrix'!$B$2:$J$56,MATCH($F8,'Permission matrix'!$A$2:$A$56,0),MATCH(O$1,'Permission matrix'!$B$1:$J$1,0))=1,"Yes","-"),"?"))))
A9: Menu setting | B9: Menu codes | C9: /menu/codes | D9: Staff (web/PWA) | E9: Table of dish and variant codes for external reference. Withheld from waiters on purpose. | F9: menu.manage | G9: =IF($F9="(none - every role)","All",IF($F9="DEV","Dev build",IF($F9="GUEST","n/a - guest",IFERROR(IF(INDEX('Permission matrix'!$B$2:$J$56,MATCH($F9,'Permission matrix'!$A$2:$A$56,0),MATCH(G$1,'Permission matrix'!$B$1:$J$1,0))=1,"Yes","-"),"?")))) | H9: =IF($F9="(none - every role)","All",IF($F9="DEV","Dev build",IF($F9="GUEST","n/a - guest",IFERROR(IF(INDEX('Permission matrix'!$B$2:$J$56,MATCH($F9,'Permission matrix'!$A$2:$A$56,0),MATCH(H$1,'Permission matrix'!$B$1:$J$1,0))=1,"Yes","-"),"?")))) | I9: =IF($F9="(none - every role)","All",IF($F9="DEV","Dev build",IF($F9="GUEST","n/a - guest",IFERROR(IF(INDEX('Permission matrix'!$B$2:$J$56,MATCH($F9,'Permission matrix'!$A$2:$A$56,0),MATCH(I$1,'Permission matrix'!$B$1:$J$1,0))=1,"Yes","-"),"?")))) | J9: =IF($F9="(none - every role)","All",IF($F9="DEV","Dev build",IF($F9="GUEST","n/a - guest",IFERROR(IF(INDEX('Permission matrix'!$B$2:$J$56,MATCH($F9,'Permission matrix'!$A$2:$A$56,0),MATCH(J$1,'Permission matrix'!$B$1:$J$1,0))=1,"Yes","-"),"?")))) | K9: =IF($F9="(none - every role)","All",IF($F9="DEV","Dev build",IF($F9="GUEST","n/a - guest",IFERROR(IF(INDEX('Permission matrix'!$B$2:$J$56,MATCH($F9,'Permission matrix'!$A$2:$A$56,0),MATCH(K$1,'Permission matrix'!$B$1:$J$1,0))=1,"Yes","-"),"?")))) | L9: =IF($F9="(none - every role)","All",IF($F9="DEV","Dev build",IF($F9="GUEST","n/a - guest",IFERROR(IF(INDEX('Permission matrix'!$B$2:$J$56,MATCH($F9,'Permission matrix'!$A$2:$A$56,0),MATCH(L$1,'Permission matrix'!$B$1:$J$1,0))=1,"Yes","-"),"?")))) | M9: =IF($F9="(none - every role)","All",IF($F9="DEV","Dev build",IF($F9="GUEST","n/a - guest",IFERROR(IF(INDEX('Permission matrix'!$B$2:$J$56,MATCH($F9,'Permission matrix'!$A$2:$A$56,0),MATCH(M$1,'Permission matrix'!$B$1:$J$1,0))=1,"Yes","-"),"?")))) | N9: =IF($F9="(none - every role)","All",IF($F9="DEV","Dev build",IF($F9="GUEST","n/a - guest",IFERROR(IF(INDEX('Permission matrix'!$B$2:$J$56,MATCH($F9,'Permission matrix'!$A$2:$A$56,0),MATCH(N$1,'Permission matrix'!$B$1:$J$1,0))=1,"Yes","-"),"?")))) | O9: =IF($F9="(none - every role)","All",IF($F9="DEV","Dev build",IF($F9="GUEST","n/a - guest",IFERROR(IF(INDEX('Permission matrix'!$B$2:$J$56,MATCH($F9,'Permission matrix'!$A$2:$A$56,0),MATCH(O$1,'Permission matrix'!$B$1:$J$1,0))=1,"Yes","-"),"?"))))
A10: Recipes & costing | B10: Stock items & recipes | C10: /stock | D10: Staff (web/PWA) | E10: Ingredient master and the recipes built from it. Writes need recipe.manage. | F10: recipe.view | G10: =IF($F10="(none - every role)","All",IF($F10="DEV","Dev build",IF($F10="GUEST","n/a - guest",IFERROR(IF(INDEX('Permission matrix'!$B$2:$J$56,MATCH($F10,'Permission matrix'!$A$2:$A$56,0),MATCH(G$1,'Permission matrix'!$B$1:$J$1,0))=1,"Yes","-"),"?")))) | H10: =IF($F10="(none - every role)","All",IF($F10="DEV","Dev build",IF($F10="GUEST","n/a - guest",IFERROR(IF(INDEX('Permission matrix'!$B$2:$J$56,MATCH($F10,'Permission matrix'!$A$2:$A$56,0),MATCH(H$1,'Permission matrix'!$B$1:$J$1,0))=1,"Yes","-"),"?")))) | I10: =IF($F10="(none - every role)","All",IF($F10="DEV","Dev build",IF($F10="GUEST","n/a - guest",IFERROR(IF(INDEX('Permission matrix'!$B$2:$J$56,MATCH($F10,'Permission matrix'!$A$2:$A$56,0),MATCH(I$1,'Permission matrix'!$B$1:$J$1,0))=1,"Yes","-"),"?")))) | J10: =IF($F10="(none - every role)","All",IF($F10="DEV","Dev build",IF($F10="GUEST","n/a - guest",IFERROR(IF(INDEX('Permission matrix'!$B$2:$J$56,MATCH($F10,'Permission matrix'!$A$2:$A$56,0),MATCH(J$1,'Permission matrix'!$B$1:$J$1,0))=1,"Yes","-"),"?")))) | K10: =IF($F10="(none - every role)","All",IF($F10="DEV","Dev build",IF($F10="GUEST","n/a - guest",IFERROR(IF(INDEX('Permission matrix'!$B$2:$J$56,MATCH($F10,'Permission matrix'!$A$2:$A$56,0),MATCH(K$1,'Permission matrix'!$B$1:$J$1,0))=1,"Yes","-"),"?")))) | L10: =IF($F10="(none - every role)","All",IF($F10="DEV","Dev build",IF($F10="GUEST","n/a - guest",IFERROR(IF(INDEX('Permission matrix'!$B$2:$J$56,MATCH($F10,'Permission matrix'!$A$2:$A$56,0),MATCH(L$1,'Permission matrix'!$B$1:$J$1,0))=1,"Yes","-"),"?")))) | M10: =IF($F10="(none - every role)","All",IF($F10="DEV","Dev build",IF($F10="GUEST","n/a - guest",IFERROR(IF(INDEX('Permission matrix'!$B$2:$J$56,MATCH($F10,'Permission matrix'!$A$2:$A$56,0),MATCH(M$1,'Permission matrix'!$B$1:$J$1,0))=1,"Yes","-"),"?")))) | N10: =IF($F10="(none - every role)","All",IF($F10="DEV","Dev build",IF($F10="GUEST","n/a - guest",IFERROR(IF(INDEX('Permission matrix'!$B$2:$J$56,MATCH($F10,'Permission matrix'!$A$2:$A$56,0),MATCH(N$1,'Permission matrix'!$B$1:$J$1,0))=1,"Yes","-"),"?")))) | O10: =IF($F10="(none - every role)","All",IF($F10="DEV","Dev build",IF($F10="GUEST","n/a - guest",IFERROR(IF(INDEX('Permission matrix'!$B$2:$J$56,MATCH($F10,'Permission matrix'!$A$2:$A$56,0),MATCH(O$1,'Permission matrix'!$B$1:$J$1,0))=1,"Yes","-"),"?"))))
A11: Recipes & costing | B11: Recipe editor | C11: /recipes/:variantId | D11: Staff (web/PWA) | E11: One variant's recipe version: ingredients, quantities, yield. The chef's screen. | F11: recipe.view | G11: =IF($F11="(none - every role)","All",IF($F11="DEV","Dev build",IF($F11="GUEST","n/a - guest",IFERROR(IF(INDEX('Permission matrix'!$B$2:$J$56,MATCH($F11,'Permission matrix'!$A$2:$A$56,0),MATCH(G$1,'Permission matrix'!$B$1:$J$1,0))=1,"Yes","-"),"?")))) | H11: =IF($F11="(none - every role)","All",IF($F11="DEV","Dev build",IF($F11="GUEST","n/a - guest",IFERROR(IF(INDEX('Permission matrix'!$B$2:$J$56,MATCH($F11,'Permission matrix'!$A$2:$A$56,0),MATCH(H$1,'Permission matrix'!$B$1:$J$1,0))=1,"Yes","-"),"?")))) | I11: =IF($F11="(none - every role)","All",IF($F11="DEV","Dev build",IF($F11="GUEST","n/a - guest",IFERROR(IF(INDEX('Permission matrix'!$B$2:$J$56,MATCH($F11,'Permission matrix'!$A$2:$A$56,0),MATCH(I$1,'Permission matrix'!$B$1:$J$1,0))=1,"Yes","-"),"?")))) | J11: =IF($F11="(none - every role)","All",IF($F11="DEV","Dev build",IF($F11="GUEST","n/a - guest",IFERROR(IF(INDEX('Permission matrix'!$B$2:$J$56,MATCH($F11,'Permission matrix'!$A$2:$A$56,0),MATCH(J$1,'Permission matrix'!$B$1:$J$1,0))=1,"Yes","-"),"?")))) | K11: =IF($F11="(none - every role)","All",IF($F11="DEV","Dev build",IF($F11="GUEST","n/a - guest",IFERROR(IF(INDEX('Permission matrix'!$B$2:$J$56,MATCH($F11,'Permission matrix'!$A$2:$A$56,0),MATCH(K$1,'Permission matrix'!$B$1:$J$1,0))=1,"Yes","-"),"?")))) | L11: =IF($F11="(none - every role)","All",IF($F11="DEV","Dev build",IF($F11="GUEST","n/a - guest",IFERROR(IF(INDEX('Permission matrix'!$B$2:$J$56,MATCH($F11,'Permission matrix'!$A$2:$A$56,0),MATCH(L$1,'Permission matrix'!$B$1:$J$1,0))=1,"Yes","-"),"?")))) | M11: =IF($F11="(none - every role)","All",IF($F11="DEV","Dev build",IF($F11="GUEST","n/a - guest",IFERROR(IF(INDEX('Permission matrix'!$B$2:$J$56,MATCH($F11,'Permission matrix'!$A$2:$A$56,0),MATCH(M$1,'Permission matrix'!$B$1:$J$1,0))=1,"Yes","-"),"?")))) | N11: =IF($F11="(none - every role)","All",IF($F11="DEV","Dev build",IF($F11="GUEST","n/a - guest",IFERROR(IF(INDEX('Permission matrix'!$B$2:$J$56,MATCH($F11,'Permission matrix'!$A$2:$A$56,0),MATCH(N$1,'Permission matrix'!$B$1:$J$1,0))=1,"Yes","-"),"?")))) | O11: =IF($F11="(none - every role)","All",IF($F11="DEV","Dev build",IF($F11="GUEST","n/a - guest",IFERROR(IF(INDEX('Permission matrix'!$B$2:$J$56,MATCH($F11,'Permission matrix'!$A$2:$A$56,0),MATCH(O$1,'Permission matrix'!$B$1:$J$1,0))=1,"Yes","-"),"?"))))
A12: Recipes & costing | B12: Dish cost | C12: /costs | D12: Staff (web/PWA) | E12: What each dish costs and earns. Deliberately not the chef's: grams, not rupees. | F12: cost.view | G12: =IF($F12="(none - every role)","All",IF($F12="DEV","Dev build",IF($F12="GUEST","n/a - guest",IFERROR(IF(INDEX('Permission matrix'!$B$2:$J$56,MATCH($F12,'Permission matrix'!$A$2:$A$56,0),MATCH(G$1,'Permission matrix'!$B$1:$J$1,0))=1,"Yes","-"),"?")))) | H12: =IF($F12="(none - every role)","All",IF($F12="DEV","Dev build",IF($F12="GUEST","n/a - guest",IFERROR(IF(INDEX('Permission matrix'!$B$2:$J$56,MATCH($F12,'Permission matrix'!$A$2:$A$56,0),MATCH(H$1,'Permission matrix'!$B$1:$J$1,0))=1,"Yes","-"),"?")))) | I12: =IF($F12="(none - every role)","All",IF($F12="DEV","Dev build",IF($F12="GUEST","n/a - guest",IFERROR(IF(INDEX('Permission matrix'!$B$2:$J$56,MATCH($F12,'Permission matrix'!$A$2:$A$56,0),MATCH(I$1,'Permission matrix'!$B$1:$J$1,0))=1,"Yes","-"),"?")))) | J12: =IF($F12="(none - every role)","All",IF($F12="DEV","Dev build",IF($F12="GUEST","n/a - guest",IFERROR(IF(INDEX('Permission matrix'!$B$2:$J$56,MATCH($F12,'Permission matrix'!$A$2:$A$56,0),MATCH(J$1,'Permission matrix'!$B$1:$J$1,0))=1,"Yes","-"),"?")))) | K12: =IF($F12="(none - every role)","All",IF($F12="DEV","Dev build",IF($F12="GUEST","n/a - guest",IFERROR(IF(INDEX('Permission matrix'!$B$2:$J$56,MATCH($F12,'Permission matrix'!$A$2:$A$56,0),MATCH(K$1,'Permission matrix'!$B$1:$J$1,0))=1,"Yes","-"),"?")))) | L12: =IF($F12="(none - every role)","All",IF($F12="DEV","Dev build",IF($F12="GUEST","n/a - guest",IFERROR(IF(INDEX('Permission matrix'!$B$2:$J$56,MATCH($F12,'Permission matrix'!$A$2:$A$56,0),MATCH(L$1,'Permission matrix'!$B$1:$J$1,0))=1,"Yes","-"),"?")))) | M12: =IF($F12="(none - every role)","All",IF($F12="DEV","Dev build",IF($F12="GUEST","n/a - guest",IFERROR(IF(INDEX('Permission matrix'!$B$2:$J$56,MATCH($F12,'Permission matrix'!$A$2:$A$56,0),MATCH(M$1,'Permission matrix'!$B$1:$J$1,0))=1,"Yes","-"),"?")))) | N12: =IF($F12="(none - every role)","All",IF($F12="DEV","Dev build",IF($F12="GUEST","n/a - guest",IFERROR(IF(INDEX('Permission matrix'!$B$2:$J$56,MATCH($F12,'Permission matrix'!$A$2:$A$56,0),MATCH(N$1,'Permission matrix'!$B$1:$J$1,0))=1,"Yes","-"),"?")))) | O12: =IF($F12="(none - every role)","All",IF($F12="DEV","Dev build",IF($F12="GUEST","n/a - guest",IFERROR(IF(INDEX('Permission matrix'!$B$2:$J$56,MATCH($F12,'Permission matrix'!$A$2:$A$56,0),MATCH(O$1,'Permission matrix'!$B$1:$J$1,0))=1,"Yes","-"),"?"))))
A13: Inventory management | B13: Stock on hand | C13: /stock/on-hand | D13: Staff (web/PWA) | E13: Current position derived from the movement ledger, plus what is expiring. | F13: stock.view | G13: =IF($F13="(none - every role)","All",IF($F13="DEV","Dev build",IF($F13="GUEST","n/a - guest",IFERROR(IF(INDEX('Permission matrix'!$B$2:$J$56,MATCH($F13,'Permission matrix'!$A$2:$A$56,0),MATCH(G$1,'Permission matrix'!$B$1:$J$1,0))=1,"Yes","-"),"?")))) | H13: =IF($F13="(none - every role)","All",IF($F13="DEV","Dev build",IF($F13="GUEST","n/a - guest",IFERROR(IF(INDEX('Permission matrix'!$B$2:$J$56,MATCH($F13,'Permission matrix'!$A$2:$A$56,0),MATCH(H$1,'Permission matrix'!$B$1:$J$1,0))=1,"Yes","-"),"?")))) | I13: =IF($F13="(none - every role)","All",IF($F13="DEV","Dev build",IF($F13="GUEST","n/a - guest",IFERROR(IF(INDEX('Permission matrix'!$B$2:$J$56,MATCH($F13,'Permission matrix'!$A$2:$A$56,0),MATCH(I$1,'Permission matrix'!$B$1:$J$1,0))=1,"Yes","-"),"?")))) | J13: =IF($F13="(none - every role)","All",IF($F13="DEV","Dev build",IF($F13="GUEST","n/a - guest",IFERROR(IF(INDEX('Permission matrix'!$B$2:$J$56,MATCH($F13,'Permission matrix'!$A$2:$A$56,0),MATCH(J$1,'Permission matrix'!$B$1:$J$1,0))=1,"Yes","-"),"?")))) | K13: =IF($F13="(none - every role)","All",IF($F13="DEV","Dev build",IF($F13="GUEST","n/a - guest",IFERROR(IF(INDEX('Permission matrix'!$B$2:$J$56,MATCH($F13,'Permission matrix'!$A$2:$A$56,0),MATCH(K$1,'Permission matrix'!$B$1:$J$1,0))=1,"Yes","-"),"?")))) | L13: =IF($F13="(none - every role)","All",IF($F13="DEV","Dev build",IF($F13="GUEST","n/a - guest",IFERROR(IF(INDEX('Permission matrix'!$B$2:$J$56,MATCH($F13,'Permission matrix'!$A$2:$A$56,0),MATCH(L$1,'Permission matrix'!$B$1:$J$1,0))=1,"Yes","-"),"?")))) | M13: =IF($F13="(none - every role)","All",IF($F13="DEV","Dev build",IF($F13="GUEST","n/a - guest",IFERROR(IF(INDEX('Permission matrix'!$B$2:$J$56,MATCH($F13,'Permission matrix'!$A$2:$A$56,0),MATCH(M$1,'Permission matrix'!$B$1:$J$1,0))=1,"Yes","-"),"?")))) | N13: =IF($F13="(none - every role)","All",IF($F13="DEV","Dev build",IF($F13="GUEST","n/a - guest",IFERROR(IF(INDEX('Permission matrix'!$B$2:$J$56,MATCH($F13,'Permission matrix'!$A$2:$A$56,0),MATCH(N$1,'Permission matrix'!$B$1:$J$1,0))=1,"Yes","-"),"?")))) | O13: =IF($F13="(none - every role)","All",IF($F13="DEV","Dev build",IF($F13="GUEST","n/a - guest",IFERROR(IF(INDEX('Permission matrix'!$B$2:$J$56,MATCH($F13,'Permission matrix'!$A$2:$A$56,0),MATCH(O$1,'Permission matrix'!$B$1:$J$1,0))=1,"Yes","-"),"?"))))
... A63: Guest (QR) | B63: Feedback | C63: /?b=<bill token> | D63: Guest (phone, no sign-in) | E63: Three questions about that visit. Needs the bill token, so staff cannot rate their own tables. | F63: GUEST | G63: =IF($F63="(none - every role)","All",IF($F63="DEV","Dev build",IF($F63="GUEST","n/a - guest",IFERROR(IF(INDEX('Permission matrix'!$B$2:$J$56,MATCH($F63,'Permission matrix'!$A$2:$A$56,0),MATCH(G$1,'Permission matrix'!$B$1:$J$1,0))=1,"Yes","-"),"?")))) | H63: =IF($F63="(none - every role)","All",IF($F63="DEV","Dev build",IF($F63="GUEST","n/a - guest",IFERROR(IF(INDEX('Permission matrix'!$B$2:$J$56,MATCH($F63,'Permission matrix'!$A$2:$A$56,0),MATCH(H$1,'Permission matrix'!$B$1:$J$1,0))=1,"Yes","-"),"?")))) | I63: =IF($F63="(none - every role)","All",IF($F63="DEV","Dev build",IF($F63="GUEST","n/a - guest",IFERROR(IF(INDEX('Permission matrix'!$B$2:$J$56,MATCH($F63,'Permission matrix'!$A$2:$A$56,0),MATCH(I$1,'Permission matrix'!$B$1:$J$1,0))=1,"Yes","-"),"?")))) | J63: =IF($F63="(none - every role)","All",IF($F63="DEV","Dev build",IF($F63="GUEST","n/a - guest",IFERROR(IF(INDEX('Permission matrix'!$B$2:$J$56,MATCH($F63,'Permission matrix'!$A$2:$A$56,0),MATCH(J$1,'Permission matrix'!$B$1:$J$1,0))=1,"Yes","-"),"?")))) | K63: =IF($F63="(none - every role)","All",IF($F63="DEV","Dev build",IF($F63="GUEST","n/a - guest",IFERROR(IF(INDEX('Permission matrix'!$B$2:$J$56,MATCH($F63,'Permission matrix'!$A$2:$A$56,0),MATCH(K$1,'Permission matrix'!$B$1:$J$1,0))=1,"Yes","-"),"?")))) | L63: =IF($F63="(none - every role)","All",IF($F63="DEV","Dev build",IF($F63="GUEST","n/a - guest",IFERROR(IF(INDEX('Permission matrix'!$B$2:$J$56,MATCH($F63,'Permission matrix'!$A$2:$A$56,0),MATCH(L$1,'Permission matrix'!$B$1:$J$1,0))=1,"Yes","-"),"?")))) | M63: =IF($F63="(none - every role)","All",IF($F63="DEV","Dev build",IF($F63="GUEST","n/a - guest",IFERROR(IF(INDEX('Permission matrix'!$B$2:$J$56,MATCH($F63,'Permission matrix'!$A$2:$A$56,0),MATCH(M$1,'Permission matrix'!$B$1:$J$1,0))=1,"Yes","-"),"?")))) | N63: =IF($F63="(none - every role)","All",IF($F63="DEV","Dev build",IF($F63="GUEST","n/a - guest",IFERROR(IF(INDEX('Permission matrix'!$B$2:$J$56,MATCH($F63,'Permission matrix'!$A$2:$A$56,0),MATCH(N$1,'Permission matrix'!$B$1:$J$1,0))=1,"Yes","-"),"?")))) | O63: =IF($F63="(none - every role)","All",IF($F63="DEV","Dev build",IF($F63="GUEST","n/a - guest",IFERROR(IF(INDEX('Permission matrix'!$B$2:$J$56,MATCH($F63,'Permission matrix'!$A$2:$A$56,0),MATCH(O$1,'Permission matrix'!$B$1:$J$1,0))=1,"Yes","-"),"?"))))

Sheet Permission matrix
A1: Permission code | B1: Owner | C1: Administrator | D1: Manager | E1: Chef | F1: Store Manager | G1: Accountant | H1: Kitchen Staff | I1: Waiter | J1: Cleaner
A2: employee.view | B2: 1 | C2: 1 | D2: 1 | E2: 1 | F2: 0 | G2: 1 | H2: 0 | I2: 0 | J2: 0
A3: employee.create | B3: 1 | C3: 1 | D3: 1 | E3: 0 | F3: 0 | G3: 0 | H3: 0 | I3: 0 | J3: 0
A4: employee.edit | B4: 1 | C4: 1 | D4: 1 | E4: 0 | F4: 0 | G4: 0 | H4: 0 | I4: 0 | J4: 0
A5: employee.deactivate | B5: 1 | C5: 1 | D5: 1 | E5: 0 | F5: 0 | G5: 0 | H5: 0 | I5: 0 | J5: 0
A6: employee.role.assign | B6: 1 | C6: 1 | D6: 1 | E6: 0 | F6: 0 | G6: 0 | H6: 0 | I6: 0 | J6: 0
A7: employee.password.reset | B7: 1 | C7: 1 | D7: 1 | E7: 0 | F7: 0 | G7: 0 | H7: 0 | I7: 0 | J7: 0
A8: role.view | B8: 1 | C8: 1 | D8: 1 | E8: 0 | F8: 0 | G8: 0 | H8: 0 | I8: 0 | J8: 0
A9: compliance.view | B9: 1 | C9: 1 | D9: 1 | E9: 0 | F9: 0 | G9: 1 | H9: 0 | I9: 0 | J9: 0
A10: compliance.act | B10: 1 | C10: 1 | D10: 0 | E10: 0 | F10: 0 | G10: 0 | H10: 0 | I10: 0 | J10: 0
A11: restaurant.configure | B11: 1 | C11: 1 | D11: 0 | E11: 0 | F11: 0 | G11: 0 | H11: 0 | I11: 0 | J11: 0
A12: menu.view | B12: 1 | C12: 1 | D12: 1 | E12: 1 | F12: 0 | G12: 0 | H12: 0 | I12: 1 | J12: 0
A13: menu.manage | B13: 1 | C13: 0 | D13: 1 | E13: 0 | F13: 0 | G13: 0 | H13: 0 | I13: 0 | J13: 0
... A56: recognition.award | B56: 1 | C56: 0 | D56: 1 | E56: 0 | F56: 0 | G56: 0 | H56: 0 | I56: 0 | J56: 0
A58: Source data, in blue: read from backend/app/core/permissions.json on 2026-09-28. 1 = the role template grants it.

Sheet Features & actions
A1: Area | B1: Feature / action | C1: Permission code | D1: What it allows | E1: Owner | F1: Administrator | G1: Manager | H1: Chef | I1: Store Manager | J1: Accountant | K1: Kitchen Staff | L1: Waiter | M1: Cleaner
A2: Analytics & reporting | B2: audit view | C2: audit.view | D2: Read the audit trail: who changed a price, who voided a bill, who granted a role, and what the value was before and after. Held by the owner, the administrator and the accountant. A manager is deliberately not given it - the person who runs the floor is frequently the subject of the record, and a record its subject curates is not a record. | E2: =IFERROR(IF(INDEX('Permission matrix'!$B$2:$J$56,MATCH($C2,'Permission matrix'!$A$2:$A$56,0),MATCH(E$1,'Permission matrix'!$B$1:$J$1,0))=1,"Yes","-"),"?") | F2: =IFERROR(IF(INDEX('Permission matrix'!$B$2:$J$56,MATCH($C2,'Permission matrix'!$A$2:$A$56,0),MATCH(F$1,'Permission matrix'!$B$1:$J$1,0))=1,"Yes","-"),"?") | G2: =IFERROR(IF(INDEX('Permission matrix'!$B$2:$J$56,MATCH($C2,'Permission matrix'!$A$2:$A$56,0),MATCH(G$1,'Permission matrix'!$B$1:$J$1,0))=1,"Yes","-"),"?") | H2: =IFERROR(IF(INDEX('Permission matrix'!$B$2:$J$56,MATCH($C2,'Permission matrix'!$A$2:$A$56,0),MATCH(H$1,'Permission matrix'!$B$1:$J$1,0))=1,"Yes","-"),"?") | I2: =IFERROR(IF(INDEX('Permission matrix'!$B$2:$J$56,MATCH($C2,'Permission matrix'!$A$2:$A$56,0),MATCH(I$1,'Permission matrix'!$B$1:$J$1,0))=1,"Yes","-"),"?") | J2: =IFERROR(IF(INDEX('Permission matrix'!$B$2:$J$56,MATCH($C2,'Permission matrix'!$A$2:$A$56,0),MATCH(J$1,'Permission matrix'!$B$1:$J$1,0))=1,"Yes","-"),"?") | K2: =IFERROR(IF(INDEX('Permission matrix'!$B$2:$J$56,MATCH($C2,'Permission matrix'!$A$2:$A$56,0),MATCH(K$1,'Permission matrix'!$B$1:$J$1,0))=1,"Yes","-"),"?") | L2: =IFERROR(IF(INDEX('Permission matrix'!$B$2:$J$56,MATCH($C2,'Permission matrix'!$A$2:$A$56,0),MATCH(L$1,'Permission matrix'!$B$1:$J$1,0))=1,"Yes","-"),"?") | M2: =IFERROR(IF(INDEX('Permission matrix'!$B$2:$J$56,MATCH($C2,'Permission matrix'!$A$2:$A$56,0),MATCH(M$1,'Permission matrix'!$B$1:$J$1,0))=1,"Yes","-"),"?")
A3: Analytics & reporting | B3: report financial view | C3: report.financial.view | D3: Read the money: revenue, covers, average bill, the payment split, and the food-cost variance that shows what was used against what the recipes say should have been. Held by the owner and the accountant. A manager is deliberately not given it - running the floor and reading the books are different jobs, and the design draws that line rather than showing a manager a screen full of blanks. | E3: =IFERROR(IF(INDEX('Permission matrix'!$B$2:$J$56,MATCH($C3,'Permission matrix'!$A$2:$A$56,0),MATCH(E$1,'Permission matrix'!$B$1:$J$1,0))=1,"Yes","-"),"?") | F3: =IFERROR(IF(INDEX('Permission matrix'!$B$2:$J$56,MATCH($C3,'Permission matrix'!$A$2:$A$56,0),MATCH(F$1,'Permission matrix'!$B$1:$J$1,0))=1,"Yes","-"),"?") | G3: =IFERROR(IF(INDEX('Permission matrix'!$B$2:$J$56,MATCH($C3,'Permission matrix'!$A$2:$A$56,0),MATCH(G$1,'Permission matrix'!$B$1:$J$1,0))=1,"Yes","-"),"?") | H3: =IFERROR(IF(INDEX('Permission matrix'!$B$2:$J$56,MATCH($C3,'Permission matrix'!$A$2:$A$56,0),MATCH(H$1,'Permission matrix'!$B$1:$J$1,0))=1,"Yes","-"),"?") | I3: =IFERROR(IF(INDEX('Permission matrix'!$B$2:$J$56,MATCH($C3,'Permission matrix'!$A$2:$A$56,0),MATCH(I$1,'Permission matrix'!$B$1:$J$1,0))=1,"Yes","-"),"?") | J3: =IFERROR(IF(INDEX('Permission matrix'!$B$2:$J$56,MATCH($C3,'Permission matrix'!$A$2:$A$56,0),MATCH(J$1,'Permission matrix'!$B$1:$J$1,0))=1,"Yes","-"),"?") | K3: =IFERROR(IF(INDEX('Permission matrix'!$B$2:$J$56,MATCH($C3,'Permission matrix'!$A$2:$A$56,0),MATCH(K$1,'Permission matrix'!$B$1:$J$1,0))=1,"Yes","-"),"?") | L3: =IFERROR(IF(INDEX('Permission matrix'!$B$2:$J$56,MATCH($C3,'Permission matrix'!$A$2:$A$56,0),MATCH(L$1,'Permission matrix'!$B$1:$J$1,0))=1,"Yes","-"),"?") | M3: =IFERROR(IF(INDEX('Permission matrix'!$B$2:$J$56,MATCH($C3,'Permission matrix'!$A$2:$A$56,0),MATCH(M$1,'Permission matrix'!$B$1:$J$1,0))=1,"Yes","-"),"?")
A4: Analytics & reporting | B4: report operational view | C4: report.operational.view | D4: Read the operational reports: what each dish sold and earned, where it sits on the menu, how long it took the kitchen, and what was thrown away. Held by a manager and a store manager as well as the owner, because these are the numbers somebody running a service can actually act on before the next one. | E4: =IFERROR(IF(INDEX('Permission matrix'!$B$2:$J$56,MATCH($C4,'Permission matrix'!$A$2:$A$56,0),MATCH(E$1,'Permission matrix'!$B$1:$J$1,0))=1,"Yes","-"),"?") | F4: =IFERROR(IF(INDEX('Permission matrix'!$B$2:$J$56,MATCH($C4,'Permission matrix'!$A$2:$A$56,0),MATCH(F$1,'Permission matrix'!$B$1:$J$1,0))=1,"Yes","-"),"?") | G4: =IFERROR(IF(INDEX('Permission matrix'!$B$2:$J$56,MATCH($C4,'Permission matrix'!$A$2:$A$56,0),MATCH(G$1,'Permission matrix'!$B$1:$J$1,0))=1,"Yes","-"),"?") | H4: =IFERROR(IF(INDEX('Permission matrix'!$B$2:$J$56,MATCH($C4,'Permission matrix'!$A$2:$A$56,0),MATCH(H$1,'Permission matrix'!$B$1:$J$1,0))=1,"Yes","-"),"?") | I4: =IFERROR(IF(INDEX('Permission matrix'!$B$2:$J$56,MATCH($C4,'Permission matrix'!$A$2:$A$56,0),MATCH(I$1,'Permission matrix'!$B$1:$J$1,0))=1,"Yes","-"),"?") | J4: =IFERROR(IF(INDEX('Permission matrix'!$B$2:$J$56,MATCH($C4,'Permission matrix'!$A$2:$A$56,0),MATCH(J$1,'Permission matrix'!$B$1:$J$1,0))=1,"Yes","-"),"?") | K4: =IFERROR(IF(INDEX('Permission matrix'!$B$2:$J$56,MATCH($C4,'Permission matrix'!$A$2:$A$56,0),MATCH(K$1,'Permission matrix'!$B$1:$J$1,0))=1,"Yes","-"),"?") | L4: =IFERROR(IF(INDEX('Permission matrix'!$B$2:$J$56,MATCH($C4,'Permission matrix'!$A$2:$A$56,0),MATCH(L$1,'Permission matrix'!$B$1:$J$1,0))=1,"Yes","-"),"?") | M4: =IFERROR(IF(INDEX('Permission matrix'!$B$2:$J$56,MATCH($C4,'Permission matrix'!$A$2:$A$56,0),MATCH(M$1,'Permission matrix'!$B$1:$J$1,0))=1,"Yes","-"),"?")
A5: Communication & tasks | B5: message send | C5: message.send | D5: Take part in the restaurant's conversations: read the threads you are in, post to them, and attach a photograph or a document. Held by every role, cleaner included, because the person who finds the broken freezer at 6am is exactly the person with no other permissions. It does not open every thread - you see a conversation because you are a participant in it, and being added to one is somebody's decision, not a permission. | E5: =IFERROR(IF(INDEX('Permission matrix'!$B$2:$J$56,MATCH($C5,'Permission matrix'!$A$2:$A$56,0),MATCH(E$1,'Permission matrix'!$B$1:$J$1,0))=1,"Yes","-"),"?") | F5: =IFERROR(IF(INDEX('Permission matrix'!$B$2:$J$56,MATCH($C5,'Permission matrix'!$A$2:$A$56,0),MATCH(F$1,'Permission matrix'!$B$1:$J$1,0))=1,"Yes","-"),"?") | G5: =IFERROR(IF(INDEX('Permission matrix'!$B$2:$J$56,MATCH($C5,'Permission matrix'!$A$2:$A$56,0),MATCH(G$1,'Permission matrix'!$B$1:$J$1,0))=1,"Yes","-"),"?") | H5: =IFERROR(IF(INDEX('Permission matrix'!$B$2:$J$56,MATCH($C5,'Permission matrix'!$A$2:$A$56,0),MATCH(H$1,'Permission matrix'!$B$1:$J$1,0))=1,"Yes","-"),"?") | I5: =IFERROR(IF(INDEX('Permission matrix'!$B$2:$J$56,MATCH($C5,'Permission matrix'!$A$2:$A$56,0),MATCH(I$1,'Permission matrix'!$B$1:$J$1,0))=1,"Yes","-"),"?") | J5: =IFERROR(IF(INDEX('Permission matrix'!$B$2:$J$56,MATCH($C5,'Permission matrix'!$A$2:$A$56,0),MATCH(J$1,'Permission matrix'!$B$1:$J$1,0))=1,"Yes","-"),"?") | K5: =IFERROR(IF(INDEX('Permission matrix'!$B$2:$J$56,MATCH($C5,'Permission matrix'!$A$2:$A$56,0),MATCH(K$1,'Permission matrix'!$B$1:$J$1,0))=1,"Yes","-"),"?") | L5: =IFERROR(IF(INDEX('Permission matrix'!$B$2:$J$56,MATCH($C5,'Permission matrix'!$A$2:$A$56,0),MATCH(L$1,'Permission matrix'!$B$1:$J$1,0))=1,"Yes","-"),"?") | M5: =IFERROR(IF(INDEX('Permission matrix'!$B$2:$J$56,MATCH($C5,'Permission matrix'!$A$2:$A$56,0),MATCH(M$1,'Permission matrix'!$B$1:$J$1,0))=1,"Yes","-"),"?")
A6: Communication & tasks | B6: task assign | C6: task.assign | D6: Give work to somebody else, move it to a different person, change what it says, cancel it, and verify that finished work was actually done. Giving a colleague a task is a manager's act, which is why it is separate from writing one down for yourself. Verifying your own completed work is refused unless you are the owner - the person who did the work is not the person who says it was done. | E6: =IFERROR(IF(INDEX('Permission matrix'!$B$2:$J$56,MATCH($C6,'Permission matrix'!$A$2:$A$56,0),MATCH(E$1,'Permission matrix'!$B$1:$J$1,0))=1,"Yes","-"),"?") | F6: =IFERROR(IF(INDEX('Permission matrix'!$B$2:$J$56,MATCH($C6,'Permission matrix'!$A$2:$A$56,0),MATCH(F$1,'Permission matrix'!$B$1:$J$1,0))=1,"Yes","-"),"?") | G6: =IFERROR(IF(INDEX('Permission matrix'!$B$2:$J$56,MATCH($C6,'Permission matrix'!$A$2:$A$56,0),MATCH(G$1,'Permission matrix'!$B$1:$J$1,0))=1,"Yes","-"),"?") | H6: =IFERROR(IF(INDEX('Permission matrix'!$B$2:$J$56,MATCH($C6,'Permission matrix'!$A$2:$A$56,0),MATCH(H$1,'Permission matrix'!$B$1:$J$1,0))=1,"Yes","-"),"?") | I6: =IFERROR(IF(INDEX('Permission matrix'!$B$2:$J$56,MATCH($C6,'Permission matrix'!$A$2:$A$56,0),MATCH(I$1,'Permission matrix'!$B$1:$J$1,0))=1,"Yes","-"),"?") | J6: =IFERROR(IF(INDEX('Permission matrix'!$B$2:$J$56,MATCH($C6,'Permission matrix'!$A$2:$A$56,0),MATCH(J$1,'Permission matrix'!$B$1:$J$1,0))=1,"Yes","-"),"?") | K6: =IFERROR(IF(INDEX('Permission matrix'!$B$2:$J$56,MATCH($C6,'Permission matrix'!$A$2:$A$56,0),MATCH(K$1,'Permission matrix'!$B$1:$J$1,0))=1,"Yes","-"),"?") | L6: =IFERROR(IF(INDEX('Permission matrix'!$B$2:$J$56,MATCH($C6,'Permission matrix'!$A$2:$A$56,0),MATCH(L$1,'Permission matrix'!$B$1:$J$1,0))=1,"Yes","-"),"?") | M6: =IFERROR(IF(INDEX('Permission matrix'!$B$2:$J$56,MATCH($C6,'Permission matrix'!$A$2:$A$56,0),MATCH(M$1,'Permission matrix'!$B$1:$J$1,0))=1,"Yes","-"),"?")
A7: Communication & tasks | B7: task complete | C7: task.complete | D7: Move a task you were assigned along its lifecycle - accept it, start it, finish it. Held by every role, and the service refuses it on somebody else's task: nobody completes work on another person's behalf, because that is the one thing the record exists to prevent. | E7: =IFERROR(IF(INDEX('Permission matrix'!$B$2:$J$56,MATCH($C7,'Permission matrix'!$A$2:$A$56,0),MATCH(E$1,'Permission matrix'!$B$1:$J$1,0))=1,"Yes","-"),"?") | F7: =IFERROR(IF(INDEX('Permission matrix'!$B$2:$J$56,MATCH($C7,'Permission matrix'!$A$2:$A$56,0),MATCH(F$1,'Permission matrix'!$B$1:$J$1,0))=1,"Yes","-"),"?") | G7: =IFERROR(IF(INDEX('Permission matrix'!$B$2:$J$56,MATCH($C7,'Permission matrix'!$A$2:$A$56,0),MATCH(G$1,'Permission matrix'!$B$1:$J$1,0))=1,"Yes","-"),"?") | H7: =IFERROR(IF(INDEX('Permission matrix'!$B$2:$J$56,MATCH($C7,'Permission matrix'!$A$2:$A$56,0),MATCH(H$1,'Permission matrix'!$B$1:$J$1,0))=1,"Yes","-"),"?") | I7: =IFERROR(IF(INDEX('Permission matrix'!$B$2:$J$56,MATCH($C7,'Permission matrix'!$A$2:$A$56,0),MATCH(I$1,'Permission matrix'!$B$1:$J$1,0))=1,"Yes","-"),"?") | J7: =IFERROR(IF(INDEX('Permission matrix'!$B$2:$J$56,MATCH($C7,'Permission matrix'!$A$2:$A$56,0),MATCH(J$1,'Permission matrix'!$B$1:$J$1,0))=1,"Yes","-"),"?") | K7: =IFERROR(IF(INDEX('Permission matrix'!$B$2:$J$56,MATCH($C7,'Permission matrix'!$A$2:$A$56,0),MATCH(K$1,'Permission matrix'!$B$1:$J$1,0))=1,"Yes","-"),"?") | L7: =IFERROR(IF(INDEX('Permission matrix'!$B$2:$J$56,MATCH($C7,'Permission matrix'!$A$2:$A$56,0),MATCH(L$1,'Permission matrix'!$B$1:$J$1,0))=1,"Yes","-"),"?") | M7: =IFERROR(IF(INDEX('Permission matrix'!$B$2:$J$56,MATCH($C7,'Permission matrix'!$A$2:$A$56,0),MATCH(M$1,'Permission matrix'!$B$1:$J$1,0))=1,"Yes","-"),"?")
A8: Communication & tasks | B8: task view | C8: task.view | D8: See the work assigned to you, and write down work for yourself. Held by every role. Somebody without task.assign sees their own tasks and the ones they created, never the whole restaurant's board. | E8: =IFERROR(IF(INDEX('Permission matrix'!$B$2:$J$56,MATCH($C8,'Permission matrix'!$A$2:$A$56,0),MATCH(E$1,'Permission matrix'!$B$1:$J$1,0))=1,"Yes","-"),"?") | F8: =IFERROR(IF(INDEX('Permission matrix'!$B$2:$J$56,MATCH($C8,'Permission matrix'!$A$2:$A$56,0),MATCH(F$1,'Permission matrix'!$B$1:$J$1,0))=1,"Yes","-"),"?") | G8: =IFERROR(IF(INDEX('Permission matrix'!$B$2:$J$56,MATCH($C8,'Permission matrix'!$A$2:$A$56,0),MATCH(G$1,'Permission matrix'!$B$1:$J$1,0))=1,"Yes","-"),"?") | H8: =IFERROR(IF(INDEX('Permission matrix'!$B$2:$J$56,MATCH($C8,'Permission matrix'!$A$2:$A$56,0),MATCH(H$1,'Permission matrix'!$B$1:$J$1,0))=1,"Yes","-"),"?") | I8: =IFERROR(IF(INDEX('Permission matrix'!$B$2:$J$56,MATCH($C8,'Permission matrix'!$A$2:$A$56,0),MATCH(I$1,'Permission matrix'!$B$1:$J$1,0))=1,"Yes","-"),"?") | J8: =IFERROR(IF(INDEX('Permission matrix'!$B$2:$J$56,MATCH($C8,'Permission matrix'!$A$2:$A$56,0),MATCH(J$1,'Permission matrix'!$B$1:$J$1,0))=1,"Yes","-"),"?") | K8: =IFERROR(IF(INDEX('Permission matrix'!$B$2:$J$56,MATCH($C8,'Permission matrix'!$A$2:$A$56,0),MATCH(K$1,'Permission matrix'!$B$1:$J$1,0))=1,"Yes","-"),"?") | L8: =IFERROR(IF(INDEX('Permission matrix'!$B$2:$J$56,MATCH($C8,'Permission matrix'!$A$2:$A$56,0),MATCH(L$1,'Permission matrix'!$B$1:$J$1,0))=1,"Yes","-"),"?") | M8: =IFERROR(IF(INDEX('Permission matrix'!$B$2:$J$56,MATCH($C8,'Permission matrix'!$A$2:$A$56,0),MATCH(M$1,'Permission matrix'!$B$1:$J$1,0))=1,"Yes","-"),"?")
A9: Compliance | B9: compliance act | C9: compliance.act | D9: Acknowledge a finding, or set one aside with a reason. Suppression is a recorded decision, not a deletion - the finding stays in the export with the reason attached, because advice ignored is still advice given, and the export is what an owner hands an inspector. The owner's and the administrator's: deciding a licence warning does not matter is not a floor decision. | E9: =IFERROR(IF(INDEX('Permission matrix'!$B$2:$J$56,MATCH($C9,'Permission matrix'!$A$2:$A$56,0),MATCH(E$1,'Permission matrix'!$B$1:$J$1,0))=1,"Yes","-"),"?") | F9: =IFERROR(IF(INDEX('Permission matrix'!$B$2:$J$56,MATCH($C9,'Permission matrix'!$A$2:$A$56,0),MATCH(F$1,'Permission matrix'!$B$1:$J$1,0))=1,"Yes","-"),"?") | G9: =IFERROR(IF(INDEX('Permission matrix'!$B$2:$J$56,MATCH($C9,'Permission matrix'!$A$2:$A$56,0),MATCH(G$1,'Permission matrix'!$B$1:$J$1,0))=1,"Yes","-"),"?") | H9: =IFERROR(IF(INDEX('Permission matrix'!$B$2:$J$56,MATCH($C9,'Permission matrix'!$A$2:$A$56,0),MATCH(H$1,'Permission matrix'!$B$1:$J$1,0))=1,"Yes","-"),"?") | I9: =IFERROR(IF(INDEX('Permission matrix'!$B$2:$J$56,MATCH($C9,'Permission matrix'!$A$2:$A$56,0),MATCH(I$1,'Permission matrix'!$B$1:$J$1,0))=1,"Yes","-"),"?") | J9: =IFERROR(IF(INDEX('Permission matrix'!$B$2:$J$56,MATCH($C9,'Permission matrix'!$A$2:$A$56,0),MATCH(J$1,'Permission matrix'!$B$1:$J$1,0))=1,"Yes","-"),"?") | K9: =IFERROR(IF(INDEX('Permission matrix'!$B$2:$J$56,MATCH($C9,'Permission matrix'!$A$2:$A$56,0),MATCH(K$1,'Permission matrix'!$B$1:$J$1,0))=1,"Yes","-"),"?") | L9: =IFERROR(IF(INDEX('Permission matrix'!$B$2:$J$56,MATCH($C9,'Permission matrix'!$A$2:$A$56,0),MATCH(L$1,'Permission matrix'!$B$1:$J$1,0))=1,"Yes","-"),"?") | M9: =IFERROR(IF(INDEX('Permission matrix'!$B$2:$J$56,MATCH($C9,'Permission matrix'!$A$2:$A$56,0),MATCH(M$1,'Permission matrix'!$B$1:$J$1,0))=1,"Yes","-"),"?")
A10: Compliance | B10: compliance view | C10: compliance.view | D10: See what in this restaurant's configuration puts its licences at risk: an expired or malformed FSSAI number, a missing GSTIN, dishes with no allergen statement. Every finding cites the instrument it comes from and the date that citation was checked, so a person can verify the product's working rather than trust it. | E10: =IFERROR(IF(INDEX('Permission matrix'!$B$2:$J$56,MATCH($C10,'Permission matrix'!$A$2:$A$56,0),MATCH(E$1,'Permission matrix'!$B$1:$J$1,0))=1,"Yes","-"),"?") | F10: =IFERROR(IF(INDEX('Permission matrix'!$B$2:$J$56,MATCH($C10,'Permission matrix'!$A$2:$A$56,0),MATCH(F$1,'Permission matrix'!$B$1:$J$1,0))=1,"Yes","-"),"?") | G10: =IFERROR(IF(INDEX('Permission matrix'!$B$2:$J$56,MATCH($C10,'Permission matrix'!$A$2:$A$56,0),MATCH(G$1,'Permission matrix'!$B$1:$J$1,0))=1,"Yes","-"),"?") | H10: =IFERROR(IF(INDEX('Permission matrix'!$B$2:$J$56,MATCH($C10,'Permission matrix'!$A$2:$A$56,0),MATCH(H$1,'Permission matrix'!$B$1:$J$1,0))=1,"Yes","-"),"?") | I10: =IFERROR(IF(INDEX('Permission matrix'!$B$2:$J$56,MATCH($C10,'Permission matrix'!$A$2:$A$56,0),MATCH(I$1,'Permission matrix'!$B$1:$J$1,0))=1,"Yes","-"),"?") | J10: =IFERROR(IF(INDEX('Permission matrix'!$B$2:$J$56,MATCH($C10,'Permission matrix'!$A$2:$A$56,0),MATCH(J$1,'Permission matrix'!$B$1:$J$1,0))=1,"Yes","-"),"?") | K10: =IFERROR(IF(INDEX('Permission matrix'!$B$2:$J$56,MATCH($C10,'Permission matrix'!$A$2:$A$56,0),MATCH(K$1,'Permission matrix'!$B$1:$J$1,0))=1,"Yes","-"),"?") | L10: =IFERROR(IF(INDEX('Permission matrix'!$B$2:$J$56,MATCH($C10,'Permission matrix'!$A$2:$A$56,0),MATCH(L$1,'Permission matrix'!$B$1:$J$1,0))=1,"Yes","-"),"?") | M10: =IFERROR(IF(INDEX('Permission matrix'!$B$2:$J$56,MATCH($C10,'Permission matrix'!$A$2:$A$56,0),MATCH(M$1,'Permission matrix'!$B$1:$J$1,0))=1,"Yes","-"),"?")
A11: Customer management | B11: complaint manage | C11: complaint.manage | D11: Log a complaint, give it an owner, and record what was actually done about it - a comp, a remake, a refund, an apology. A complaint nobody owns is worse than no system, which is why assigning is part of the same permission as logging. Whether the customer came back afterwards is not typed by anybody: it is derived from the order ledger, because it is the only honest measure of recovery and it becomes true weeks after everyone has forgotten. | E11: =IFERROR(IF(INDEX('Permission matrix'!$B$2:$J$56,MATCH($C11,'Permission matrix'!$A$2:$A$56,0),MATCH(E$1,'Permission matrix'!$B$1:$J$1,0))=1,"Yes","-"),"?") | F11: =IFERROR(IF(INDEX('Permission matrix'!$B$2:$J$56,MATCH($C11,'Permission matrix'!$A$2:$A$56,0),MATCH(F$1,'Permission matrix'!$B$1:$J$1,0))=1,"Yes","-"),"?") | G11: =IFERROR(IF(INDEX('Permission matrix'!$B$2:$J$56,MATCH($C11,'Permission matrix'!$A$2:$A$56,0),MATCH(G$1,'Permission matrix'!$B$1:$J$1,0))=1,"Yes","-"),"?") | H11: =IFERROR(IF(INDEX('Permission matrix'!$B$2:$J$56,MATCH($C11,'Permission matrix'!$A$2:$A$56,0),MATCH(H$1,'Permission matrix'!$B$1:$J$1,0))=1,"Yes","-"),"?") | I11: =IFERROR(IF(INDEX('Permission matrix'!$B$2:$J$56,MATCH($C11,'Permission matrix'!$A$2:$A$56,0),MATCH(I$1,'Permission matrix'!$B$1:$J$1,0))=1,"Yes","-"),"?") | J11: =IFERROR(IF(INDEX('Permission matrix'!$B$2:$J$56,MATCH($C11,'Permission matrix'!$A$2:$A$56,0),MATCH(J$1,'Permission matrix'!$B$1:$J$1,0))=1,"Yes","-"),"?") | K11: =IFERROR(IF(INDEX('Permission matrix'!$B$2:$J$56,MATCH($C11,'Permission matrix'!$A$2:$A$56,0),MATCH(K$1,'Permission matrix'!$B$1:$J$1,0))=1,"Yes","-"),"?") | L11: =IFERROR(IF(INDEX('Permission matrix'!$B$2:$J$56,MATCH($C11,'Permission matrix'!$A$2:$A$56,0),MATCH(L$1,'Permission matrix'!$B$1:$J$1,0))=1,"Yes","-"),"?") | M11: =IFERROR(IF(INDEX('Permission matrix'!$B$2:$J$56,MATCH($C11,'Permission matrix'!$A$2:$A$56,0),MATCH(M$1,'Permission matrix'!$B$1:$J$1,0))=1,"Yes","-"),"?")
A12: Customer management | B12: customer manage | C12: customer.manage | D12: Create and edit a customer, record their preferences, capture or withdraw a consent, export everything held about them, and erase them at their request. Erasure destroys every detail that names a person and keeps every order, because a bill is a financial record; it cannot be undone, and afterwards the same person returning is a new customer with no history. | E12: =IFERROR(IF(INDEX('Permission matrix'!$B$2:$J$56,MATCH($C12,'Permission matrix'!$A$2:$A$56,0),MATCH(E$1,'Permission matrix'!$B$1:$J$1,0))=1,"Yes","-"),"?") | F12: =IFERROR(IF(INDEX('Permission matrix'!$B$2:$J$56,MATCH($C12,'Permission matrix'!$A$2:$A$56,0),MATCH(F$1,'Permission matrix'!$B$1:$J$1,0))=1,"Yes","-"),"?") | G12: =IFERROR(IF(INDEX('Permission matrix'!$B$2:$J$56,MATCH($C12,'Permission matrix'!$A$2:$A$56,0),MATCH(G$1,'Permission matrix'!$B$1:$J$1,0))=1,"Yes","-"),"?") | H12: =IFERROR(IF(INDEX('Permission matrix'!$B$2:$J$56,MATCH($C12,'Permission matrix'!$A$2:$A$56,0),MATCH(H$1,'Permission matrix'!$B$1:$J$1,0))=1,"Yes","-"),"?") | I12: =IFERROR(IF(INDEX('Permission matrix'!$B$2:$J$56,MATCH($C12,'Permission matrix'!$A$2:$A$56,0),MATCH(I$1,'Permission matrix'!$B$1:$J$1,0))=1,"Yes","-"),"?") | J12: =IFERROR(IF(INDEX('Permission matrix'!$B$2:$J$56,MATCH($C12,'Permission matrix'!$A$2:$A$56,0),MATCH(J$1,'Permission matrix'!$B$1:$J$1,0))=1,"Yes","-"),"?") | K12: =IFERROR(IF(INDEX('Permission matrix'!$B$2:$J$56,MATCH($C12,'Permission matrix'!$A$2:$A$56,0),MATCH(K$1,'Permission matrix'!$B$1:$J$1,0))=1,"Yes","-"),"?") | L12: =IFERROR(IF(INDEX('Permission matrix'!$B$2:$J$56,MATCH($C12,'Permission matrix'!$A$2:$A$56,0),MATCH(L$1,'Permission matrix'!$B$1:$J$1,0))=1,"Yes","-"),"?") | M12: =IFERROR(IF(INDEX('Permission matrix'!$B$2:$J$56,MATCH($C12,'Permission matrix'!$A$2:$A$56,0),MATCH(M$1,'Permission matrix'!$B$1:$J$1,0))=1,"Yes","-"),"?")
A13: Customer management | B13: customer view | C13: customer.view | D13: See a customer's profile: their number, how often they have been, what they usually order and how they like it. Held by a waiter as well as a manager, because greeting a regular by name and remembering they eat no onion is the whole point of keeping the record - asking a regular for the fourth time whether they eat onion is a small insult, and remembering is a small delight. A person sees the customers of the restaurant they are working in, not the whole organization's. | E13: =IFERROR(IF(INDEX('Permission matrix'!$B$2:$J$56,MATCH($C13,'Permission matrix'!$A$2:$A$56,0),MATCH(E$1,'Permission matrix'!$B$1:$J$1,0))=1,"Yes","-"),"?") | F13: =IFERROR(IF(INDEX('Permission matrix'!$B$2:$J$56,MATCH($C13,'Permission matrix'!$A$2:$A$56,0),MATCH(F$1,'Permission matrix'!$B$1:$J$1,0))=1,"Yes","-"),"?") | G13: =IFERROR(IF(INDEX('Permission matrix'!$B$2:$J$56,MATCH($C13,'Permission matrix'!$A$2:$A$56,0),MATCH(G$1,'Permission matrix'!$B$1:$J$1,0))=1,"Yes","-"),"?") | H13: =IFERROR(IF(INDEX('Permission matrix'!$B$2:$J$56,MATCH($C13,'Permission matrix'!$A$2:$A$56,0),MATCH(H$1,'Permission matrix'!$B$1:$J$1,0))=1,"Yes","-"),"?") | I13: =IFERROR(IF(INDEX('Permission matrix'!$B$2:$J$56,MATCH($C13,'Permission matrix'!$A$2:$A$56,0),MATCH(I$1,'Permission matrix'!$B$1:$J$1,0))=1,"Yes","-"),"?") | J13: =IFERROR(IF(INDEX('Permission matrix'!$B$2:$J$56,MATCH($C13,'Permission matrix'!$A$2:$A$56,0),MATCH(J$1,'Permission matrix'!$B$1:$J$1,0))=1,"Yes","-"),"?") | K13: =IFERROR(IF(INDEX('Permission matrix'!$B$2:$J$56,MATCH($C13,'Permission matrix'!$A$2:$A$56,0),MATCH(K$1,'Permission matrix'!$B$1:$J$1,0))=1,"Yes","-"),"?") | L13: =IFERROR(IF(INDEX('Permission matrix'!$B$2:$J$56,MATCH($C13,'Permission matrix'!$A$2:$A$56,0),MATCH(L$1,'Permission matrix'!$B$1:$J$1,0))=1,"Yes","-"),"?") | M13: =IFERROR(IF(INDEX('Permission matrix'!$B$2:$J$56,MATCH($C13,'Permission matrix'!$A$2:$A$56,0),MATCH(M$1,'Permission matrix'!$B$1:$J$1,0))=1,"Yes","-"),"?")
... A56: Waste management | B56: wastage log | C56: wastage.log | D56: Record something thrown away: what, how much and why. The cost is computed by the server from the batches the stock actually came out of and is never asked of the person logging - a cook does not know what a kilo of paneer cost on the day it was delivered, and asking would either get a guess or stop them logging at all. Held by the chef, the kitchen staff, the manager and the store manager; a waiter does not hold it. | E56: =IFERROR(IF(INDEX('Permission matrix'!$B$2:$J$56,MATCH($C56,'Permission matrix'!$A$2:$A$56,0),MATCH(E$1,'Permission matrix'!$B$1:$J$1,0))=1,"Yes","-"),"?") | F56: =IFERROR(IF(INDEX('Permission matrix'!$B$2:$J$56,MATCH($C56,'Permission matrix'!$A$2:$A$56,0),MATCH(F$1,'Permission matrix'!$B$1:$J$1,0))=1,"Yes","-"),"?") | G56: =IFERROR(IF(INDEX('Permission matrix'!$B$2:$J$56,MATCH($C56,'Permission matrix'!$A$2:$A$56,0),MATCH(G$1,'Permission matrix'!$B$1:$J$1,0))=1,"Yes","-"),"?") | H56: =IFERROR(IF(INDEX('Permission matrix'!$B$2:$J$56,MATCH($C56,'Permission matrix'!$A$2:$A$56,0),MATCH(H$1,'Permission matrix'!$B$1:$J$1,0))=1,"Yes","-"),"?") | I56: =IFERROR(IF(INDEX('Permission matrix'!$B$2:$J$56,MATCH($C56,'Permission matrix'!$A$2:$A$56,0),MATCH(I$1,'Permission matrix'!$B$1:$J$1,0))=1,"Yes","-"),"?") | J56: =IFERROR(IF(INDEX('Permission matrix'!$B$2:$J$56,MATCH($C56,'Permission matrix'!$A$2:$A$56,0),MATCH(J$1,'Permission matrix'!$B$1:$J$1,0))=1,"Yes","-"),"?") | K56: =IFERROR(IF(INDEX('Permission matrix'!$B$2:$J$56,MATCH($C56,'Permission matrix'!$A$2:$A$56,0),MATCH(K$1,'Permission matrix'!$B$1:$J$1,0))=1,"Yes","-"),"?") | L56: =IFERROR(IF(INDEX('Permission matrix'!$B$2:$J$56,MATCH($C56,'Permission matrix'!$A$2:$A$56,0),MATCH(L$1,'Permission matrix'!$B$1:$J$1,0))=1,"Yes","-"),"?") | M56: =IFERROR(IF(INDEX('Permission matrix'!$B$2:$J$56,MATCH($C56,'Permission matrix'!$A$2:$A$56,0),MATCH(M$1,'Permission matrix'!$B$1:$J$1,0))=1,"Yes","-"),"?")

Sheet Roles
